Workbook

Sheet input sheet
B1: order | C1: Adnaan
C2: bic
A3: kitchen spec
E4: board colour | F4: white
C5: gola | E5: colour edge 1 | F5: tbc
A6: floor unit hight | B6: 720 | C6: no
A7: floor depth | B7: 560
A8: wall unit hight | B8: 1080
A9: wall unit hight | B9: 720
A10: wall depth | B10: 300
A11: tall unit hight | B11: 2296 | D11: calculates as you adjust tall wall and floor unit
A12: tall depth | B12: 580
E13: edge colour
A14: floor | B14: greater than 600
B15: 541 | C15: doors | D15: 1 | E15: 1
B16: 600 | C16: uco | E16: 1
B17: 600 | C17: doors | D17: 2 | E17: 1
B18: 600 | C18: 4 draw st | D18: 500 | E18: 1
B19: 700 | C19: 3 draw st | D19: 500 | E19: 1
B20: 600 | C20: 2 draw pot st | D20: 500 | E20: 1
B21: 750 | E21: 1
B22: 750 | C22: 3 draw st | D22: 500 | E22: 1
B23: 900 | C23: crn | D23: 900 | E23: 1
B24: 1000 | C24: crn spec | D24: 900 | E24: 1 | F24: 750
B25: 900 | E25: 1
B26: 900 | C26: 3 draw st | D26: 500 | E26: 1
B27: 1000 | E27: 1
B28: 1100 | E28: 1
B29: 1200 | E29: 1
B30: 1200 | E30: 1
A31: floor | B31: smaller than 600
B32: 300 | E32: 1
B33: 450 | E33: 1
B34: 450 | C34: 4 draw st | D34: 500 | E34: 1
B35: 450 | C35: 3 draw st | D35: 500 | E35: 1
B36: 450 | C36: bin | D36: 500 | E36: 1
B37: 200 | E37: 1
B38: 150 | D38: special | E38: 1
A39: wall units high
B40: 900
...

Sheet cut list
A1: client name | B1: =+'input sheet'!C1 -> Adnaan | C1: =IF('input sheet'!C6="Yes",1,0) -> 0 | E1: board colour | F1: =+'input sheet'!F4 -> white
A2: Project name | B2: =+'input sheet'!C2 -> bic | C2: gola | E2: edge colour 1 | F2: =+'input sheet'!F5:G5 -> tbc
B3: floor unit height | C3: =+'input sheet'!B6 -> 720 | E3: edge colour 2 | F3: =+'input sheet'!F6 -> 0
B4: floor depth | C4: ='input sheet'!B7 -> 560
B5: wall unit height | C5: ='input sheet'!B8 -> 1080
B6: wall unit height | C6: =+'input sheet'!B9 -> 720
B7: wall depth | C7: ='input sheet'!B10 -> 300 | E7: do not change
B8: tall unit height | C8: ='input sheet'!B11 -> 2296
B9: tall depth | C9: ='input sheet'!B12 -> 580
B10: 1 | E10: long edge | F10: short edge | G10: edge material | H10: board material | J10: description
A11: =+'input sheet'!B15 -> 541 | B11: =+A12 -> 0 | C11: floor | D11: =+'input sheet'!C15 -> doors | E11: =+'input sheet'!D15 -> 1 | F11: =+(C13-3)-(C$1*35) -> 717 | G11: =+A11-3 -> 538 | H11: =+B11*1 -> 0
A12: =+'input sheet'!A15 -> 0
B13: =+A12*2 -> 0 | C13: =+$C$3 -> 720 | D13: =+$C$4 -> 560 | E13: 1 | G13: =+F$2 -> tbc | H13: =+F$1 -> white | J13: sides
B14: =+A12*1 -> 0 | C14: =+A11-32 -> 509 | D14: =+$C$4 -> 560 | E14: 1 | G14: =+F$2 -> tbc | H14: =+F$1 -> white | J14: base
B15: =+A12*1 -> 0 | C15: =+A11-32 -> 509 | D15: =+C$4-26 -> 534 | E15: 1 | G15: =+F$2 -> tbc | H15: =+F$1 -> white | J15: shelf
B16: =+A12*1 -> 0 | C16: =+A11-32 -> 509 | D16: 125 | E16: 1 | G16: =+F$2 -> tbc | H16: =+F$1 -> white | J16: cleat
B17: =+A12*1 -> 0 | C17: =+$C$3-17 -> 703 | D17: =+A11-32 -> 509 | G17: =+F$2 -> tbc | H17: =+F$1 -> white | J17: back
A18: =+'input sheet'!B16 -> 600 | B18: =+A19 -> 0 | C18: =+'input sheet'!C16 -> uco | F18: 120 | G18: =+A18-3 -> 597 | H18: =+B18*1 -> 0
A19: =+'input sheet'!A16 -> 0
B20: =+B18*2 -> 0 | C20: =+C3 -> 720 | D20: 100 | E20: 1 | G20: =+F$2 -> tbc | H20: =+F$1 -> white | J20: sides
B21: =+B18 -> 0 | C21: =+A18 -> 600 | D21: =+$C$4 -> 560 | E21: 1 | G21: =+F$2 -> tbc | H21: =+F$1 -> white | J21: base
B22: =+B18*1 -> 0 | C22: =+A18-32 -> 568 | D22: =+D20 -> 100 | E22: 1 | G22: =+F$2 -> tbc | H22: =+F$1 -> white | J22: shelf
B23: =+B18*2 -> 0 | C23: =+A18 -> 600 | D23: =+D22 -> 100 | E23: 1 | G23: =+F$2 -> tbc | H23: =+F$1 -> white | J23: cleat
A24: =+'input sheet'!B17 -> 600 | B24: =+A25 -> 0 | C24: floor | D24: =+'input sheet'!C17 -> doors | E24: =+'input sheet'!D17 -> 2 | F24: =+(C26-3)-(C$1*35) -> 717 | G24: =+A24/2-3 -> 297 | H24: =+B24*2 -> 0
A25: =+'input sheet'!A17 -> 0
B26: =+A25*2 -> 0 | C26: =+$C$3 -> 720 | D26: =+$C$4 -> 560 | E26: 1 | G26: =+F$2 -> tbc | H26: =+F$1 -> white | J26: sides
B27: =+A25*1 -> 0 | C27: =+A24-32 -> 568 | D27: =+$C$4 -> 560 | E27: 1 | G27: =+F$2 -> tbc | H27: =+F$1 -> white | J27: base
B28: =+A25*1 -> 0 | C28: =+A24-32 -> 568 | D28: =+C$4-26 -> 534 | E28: 1 | G28: =+F$2 -> tbc | H28: =+F$1 -> white | J28: shelf
B29: =+A25*1 -> 0 | C29: =+A24-32 -> 568 | D29: 125 | E29: 1 | G29: =+F$2 -> tbc | H29: =+F$1 -> white | J29: cleat
B30: =+A25*1 -> 0 | C30: =+$C$3-17 -> 703 | D30: =+A24-32 -> 568 | G30: =+F$2 -> tbc | H30: =+F$1 -> white | J30: back
A31: =+'input sheet'!B18 -> 600 | B31: =+A32 -> 0 | C31: floor | D31: =+'input sheet'!D18 -> 500 | E31: =+'input sheet'!C18 -> 4 draw st | F31: =+C33/4-3 -> 177 | G31: =+A31-3 -> 597 | H31: =+B31*4 -> 0
A32: =+'input sheet'!A18 -> 0
B33: =+A32*2 -> 0 | C33: =+$C$3 -> 720 | D33: =+$C$4 -> 560 | E33: 1 | G33: =+F$2 -> tbc | H33: =+F$1 -> white | J33: sides
B34: =+A32*1 -> 0 | C34: =+A31-32 -> 568 | D34: =+$C$4 -> 560 | E34: 1 | G34: =+F$2 -> tbc | H34: =+F$1 -> white | J34: base
B35: =+A32*1 -> 0 | C35: =+A31-32 -> 568 | D35: 125 | E35: 1 | G35: =+F$2 -> tbc | H35: =+F$1 -> white | J35: cleat
B36: =+A32*1 -> 0 | C36: =+$C$3-17 -> 703 | D36: =+A31-32 -> 568 | G36: =+F$2 -> tbc | H36: =+F$1 -> white | J36: back
B37: =+A32*8 -> 0 | C37: =+A31-90 -> 510 | D37: 127 | E37: 1 | G37: =+F$2 -> tbc | H37: =+F$1 -> white | J37: draw inner fr back
B38: =+A32*4 -> 0 | C38: =+A31-90 -> 510 | D38: =+D31-32 -> 468 | G38: =+F$2 -> tbc | H38: =+F$1 -> white | J38: draw base
B39: =A32*8 -> 0 | C39: =+D31 -> 500 | D39: 127 | E39: 1 | G39: =+F$2 -> tbc | H39: =+F$1 -> white | J39: draw sides
A40: =+'input sheet'!B19 -> 700 | B40: =+A41 -> 0 | C40: floor | D40: =+'input sheet'!D19 -> 500 | E40: =+'input sheet'!C19 -> 3 draw st | F40: 177 | G40: 356 | H40: =+A40-3 -> 697 | I40: =+B40*2 -> 0 | J40: =+B40*1 -> 0
...

Sheet doors
A1: Door Board List
A2: Client Name : | C2: =+'input sheet'!C1 -> Adnaan | F2: Date : | G2: 45479 | I2: door colour | J2: door edge | K2: gola | L2: =-35*M2 -> 0 | M2: 0
A3: Job Reference : | C3: =+'input sheet'!C2 -> bic | I3: tbc | J3: tbc | K3: no
A5: Delivery Address:
A6: Index | B6: Name | C6: Height | D6: Thickness | E6: Width | F6: Quantity | G6: Area | H6: Unit | I6: Door Color | J6: door edge | K6: Door Edge | L6: UnitPrice | M6: Total | N6: pot holes
A7: 1 | B7: door | C7: =+'cut list'!F11 -> 717 | E7: =+'cut list'!G11 -> 538 | F7: =+'cut list'!H11 -> 0 | G7: =+F7*E7/1000*C7/1000 -> 0 | H7: m2 | I7: =+I$3 -> tbc | J7: =+J$3 -> tbc | K7: ear | L7: 375 | M7: =L7*G7 -> 0 | N7: 2
A8: 2 | B8: draw front | C8: =+'cut list'!F18 -> 120 | E8: =+'cut list'!G18 -> 597 | F8: =+'cut list'!H18 -> 0 | G8: =+F8*E8/1000*C8/1000 -> 0 | H8: m2 | I8: =+I$3 -> tbc | J8: =+J$3 -> tbc | K8: ear | L8: 375 | M8: =L8*G8 -> 0
A9: 3 | B9: door | C9: =+'cut list'!F24 -> 717 | E9: =+'cut list'!G24 -> 297 | F9: =+'cut list'!H24 -> 0 | G9: =+F9*E9/1000*C9/1000 -> 0 | H9: m2 | I9: =+I$3 -> tbc | J9: =+J$3 -> tbc | K9: ear | L9: 375 | M9: =L9*G9 -> 0 | N9: 2
A10: 4 | B10: draw front | C10: =+'cut list'!F31 -> 177 | E10: =+'cut list'!G31 -> 597 | F10: =+'cut list'!H31 -> 0 | G10: =+F10*E10/1000*C10/1000 -> 0 | H10: m2 | I10: =+I$3 -> tbc | J10: =+J$3 -> tbc | K10: ear | L10: 375 | M10: =L10*G10 -> 0
A11: 5 | B11: draw front | C11: =+'cut list'!F40 -> 177 | E11: =+'cut list'!H40 -> 697 | F11: =+'cut list'!I40 -> 0 | G11: =+F11*E11/1000*C11/1000 -> 0 | H11: m2 | I11: =+I$3 -> tbc | J11: =+J$3 -> tbc | K11: ear | L11: 375 | M11: =L11*G11 -> 0
A12: 6 | B12: draw front | C12: =+'cut list'!G40 -> 356 | E12: =+'cut list'!H40 -> 697 | F12: =+'cut list'!J40 -> 0 | G12: =+F12*E12/1000*C12/1000 -> 0 | H12: m2 | I12: =+I$3 -> tbc | J12: =+J$3 -> tbc | K12: ear | L12: 375 | M12: =L12*G12 -> 0
A13: 7 | B13: draw front | C13: =+'cut list'!F51 -> 356 | E13: =+'cut list'!H51 -> 597 | F13: =+'cut list'!I51 -> 0 | G13: =+F13*E13/1000*C13/1000 -> 0 | H13: m2 | I13: =+I$3 -> tbc | J13: =+J$3 -> tbc | K13: ear | L13: 375 | M13: =L13*G13 -> 0
A14: 8 | B14: door | C14: =+'cut list'!F60 -> 717 | E14: =+'cut list'!G60 -> 372 | F14: =+'cut list'!H60 -> 0 | G14: =+F14*E14/1000*C14/1000 -> 0 | H14: m2 | I14: =+I$3 -> tbc | J14: =+J$3 -> tbc | K14: ear | L14: 375 | M14: =L14*G14 -> 0 | N14: 2
A15: 8 | B15: draw front | C15: =+'cut list'!F67 -> 177 | E15: =+'cut list'!H67 -> 747 | F15: =+'cut list'!I67 -> 0 | G15: =+F15*E15/1000*C15/1000 -> 0 | H15: m2 | I15: =+I$3 -> tbc | J15: =+J$3 -> tbc | K15: ear | L15: 375 | M15: =L15*G15 -> 0
A16: 9 | B16: draw front | C16: =+'cut list'!G67 -> 356 | E16: =+'cut list'!H67 -> 747 | F16: =+'cut list'!J67 -> 0 | G16: =+F16*E16/1000*C16/1000 -> 0 | H16: m2 | I16: =+I$3 -> tbc | J16: =+J$3 -> tbc | K16: ear | L16: 375 | M16: =L16*G16 -> 0
A17: 10 | B17: door | C17: =+'cut list'!F78 -> 717 | E17: =+'cut list'!G78 -> 316 | F17: =+'cut list'!I78 -> 0 | G17: =+F17*E17/1000*C17/1000 -> 0 | H17: m2 | I17: =+I$3 -> tbc | J17: =+J$3 -> tbc | K17: ear | L17: 375 | M17: =L17*G17 -> 0 | N17: 2
A18: 11 | B18: door | C18: =+'cut list'!F78 -> 717 | E18: =+'cut list'!H78 -> 319 | F18: =+'cut list'!J78 -> 0 | G18: =+F18*E18/1000*C18/1000 -> 0 | H18: m2 | I18: =+I$3 -> tbc | J18: =+J$3 -> tbc | K18: ear | L18: 375 | M18: =L18*G18 -> 0 | N18: 2
A19: 12 | B19: door | C19: =+'cut list'!F84 -> 717 | E19: =+'cut list'!G84 -> 316 | F19: =+'cut list'!I84 -> 0 | G19: =+F19*E19/1000*C19/1000 -> 0 | H19: m2 | I19: =+I$3 -> tbc | J19: =+J$3 -> tbc | K19: ear | L19: 375 | M19: =L19*G19 -> 0 | N19: 2
A20: 13 | B20: door | C20: =+'cut list'!F84 -> 717 | E20: =+'cut list'!H84 -> 419 | F20: =+'cut list'!J84 -> 0 | G20: =+F20*E20/1000*C20/1000 -> 0 | H20: m2 | I20: =+I$3 -> tbc | J20: =+J$3 -> tbc | K20: ear | L20: 375 | M20: =L20*G20 -> 0 | N20: 2
A21: 14 | B21: door | C21: =+'cut list'!F91 -> 717 | E21: =+'cut list'!G91 -> 447 | F21: =+'cut list'!I91 -> 0 | G21: =+F21*E21/1000*C21/1000 -> 0 | H21: m2 | I21: =+I$3 -> tbc | J21: =+J$3 -> tbc | K21: ear | L21: 375 | M21: =L21*G21 -> 0 | N21: 2
A22: 15 | B22: draw front | C22: =+'cut list'!F98 -> 177 | E22: =+'cut list'!H98 -> 897 | F22: =+'cut list'!I98 -> 0 | G22: =+F22*E22/1000*C22/1000 -> 0 | H22: m2 | I22: =+I$3 -> tbc | J22: =+J$3 -> tbc | K22: ear | L22: 375 | M22: =L22*G22 -> 0
A23: 16 | B23: draw front | C23: =++'cut list'!G98 -> 356 | E23: =+'cut list'!H98 -> 897 | F23: =+'cut list'!J98 -> 0 | G23: =+F23*E23/1000*C23/1000 -> 0 | H23: m2 | I23: =+I$3 -> tbc | J23: =+J$3 -> tbc | K23: ear | L23: 375 | M23: =L23*G23 -> 0
A24: 17 | B24: door | C24: =+'cut list'!F109 -> 717 | E24: =+'cut list'!G109 -> 497 | F24: =+'cut list'!I109 -> 0 | G24: =+F24*E24/1000*C24/1000 -> 0 | H24: m2 | I24: =+I$3 -> tbc | J24: =+J$3 -> tbc | K24: ear | L24: 375 | M24: =L24*G24 -> 0 | N24: 2
A25: 18 | B25: door | C25: =+'cut list'!F116 -> 717 | E25: =+'cut list'!G116 -> 547 | F25: =+'cut list'!I116 -> 0 | G25: =+F25*E25/1000*C25/1000 -> 0 | H25: m2 | I25: =+I$3 -> tbc | J25: =+J$3 -> tbc | K25: ear | L25: 375 | M25: =L25*G25 -> 0 | N25: 2
A26: 19 | B26: door | C26: =+'cut list'!F123 -> 717 | E26: =+'cut list'!G123 -> 597 | F26: =+'cut list'!I123 -> 0 | G26: =+F26*E26/1000*C26/1000 -> 0 | H26: m2 | I26: =+I$3 -> tbc | J26: =+J$3 -> tbc | K26: ear | L26: 375 | M26: =L26*G26 -> 0 | N26: 2
A27: 20 | B27: door | C27: =+'cut list'!F130 -> 717 | E27: =+'cut list'!G130 -> 597 | F27: =+'cut list'!I130 -> 0 | G27: =+F27*E27/1000*C27/1000 -> 0 | H27: m2 | I27: =+I$3 -> tbc | J27: =+J$3 -> tbc | K27: ear | L27: 375 | M27: =L27*G27 -> 0 | N27: 2
A28: 21 | B28: door | C28: =+'cut list'!F137 -> 717 | E28: =+'cut list'!G137 -> 297 | F28: =+'cut list'!I137 -> 0 | G28: =+F28*E28/1000*C28/1000 -> 0 | H28: m2 | I28: =+I$3 -> tbc | J28: =+J$3 -> tbc | K28: ear | L28: 375 | M28: =L28*G28 -> 0 | N28: 2
A29: 22 | B29: door | C29: =+'cut list'!F144 -> 717 | E29: =+'cut list'!G144 -> 447 | F29: =+'cut list'!I144 -> 0 | G29: =+F29*E29/1000*C29/1000 -> 0 | H29: m2 | I29: =+I$3 -> tbc | J29: =+J$3 -> tbc | K29: ear | L29: 375 | M29: =L29*G29 -> 0 | N29: 2
A30: 23 | B30: draw front | C30: =+'cut list'!F151 -> 177 | E30: =+'cut list'!G151 -> 447 | F30: =+'cut list'!H151 -> 0 | G30: =+F30*E30/1000*C30/1000 -> 0 | H30: m2 | I30: =+I$3 -> tbc | J30: =+J$3 -> tbc | K30: ear | L30: 375 | M30: =L30*G30 -> 0
A31: 24 | B31: draw front | C31: =+'cut list'!F160 -> 177 | E31: =+'cut list'!H160 -> 447 | F31: =+'cut list'!I160 -> 0 | G31: =+F31*E31/1000*C31/1000 -> 0 | H31: m2 | I31: =+I$3 -> tbc | J31: =+J$3 -> tbc | K31: ear | L31: 375 | M31: =L31*G31 -> 0
A32: 25 | B32: draw front | C32: =+'cut list'!G160 -> 356 | E32: =+'cut list'!H160 -> 447 | F32: =+'cut list'!J160 -> 0 | G32: =+F32*E32/1000*C32/1000 -> 0 | H32: m2 | I32: =+I$3 -> tbc | J32: =+J$3 -> tbc | K32: ear | L32: 375 | M32: =L32*G32 -> 0
A33: 26 | B33: draw front | C33: =+'cut list'!F171 -> 717 | E33: =+'cut list'!G171 -> 447 | F33: =+'cut list'!I171 -> 0 | G33: =+F33*E33/1000*C33/1000 -> 0 | H33: m2 | I33: =+I$3 -> tbc | J33: =+J$3 -> tbc | K33: ear | L33: 375 | M33: =L33*G33 -> 0 | N33: 2
A34: 27 | B34: door | C34: =+'cut list'!F180 -> 717 | E34: =+'cut list'!G180 -> 197 | F34: =+'cut list'!I187 -> 0 | G34: =+F34*E34/1000*C34/1000 -> 0 | H34: m2 | I34: =+I$3 -> tbc | J34: =+J$3 -> tbc | K34: ear | L34: 375 | M34: =L34*G34 -> 0 | N34: 2
A35: 28 | B35: door | C35: =+'cut list'!F187 -> 717 | E35: =+'cut list'!G187 -> 147 | F35: =+'cut list'!I187 -> 0 | G35: =+F35*E35/1000*C35/1000 -> 0 | H35: m2 | I35: =+I$3 -> tbc | J35: =+J$3 -> tbc | K35: ear | L35: 375 | M35: =L35*G35 -> 0 | N35: 2
A36: 29 | B36: door high | C36: =+'cut list'!F194 -> 1077 | E36: =+'cut list'!G194 -> 447 | F36: =+'cut list'!I194 -> 0 | G36: =+F36*E36/1000*C36/1000 -> 0 | H36: m2 | I36: =+I$3 -> tbc | J36: =+J$3 -> tbc | K36: ear | L36: 375 | M36: =L36*G36 -> 0
A37: 30 | B37: door high | C37: =+'cut list'!F206 -> 1077 | E37: =+'cut list'!G206 -> 279 | F37: =+'cut list'!I206 -> 0 | G37: =+F37*E37/1000*C37/1000 -> 0 | H37: m2 | I37: =+I$3 -> tbc | J37: =+J$3 -> tbc | K37: ear | L37: 375 | M37: =L37*G37 -> 0
A38: 31 | B38: door high | C38: =+'cut list'!F206 -> 1077 | E38: =+'cut list'!H206 -> 279 | F38: =+'cut list'!I206 -> 0 | G38: =+F38*E38/1000*C38/1000 -> 0 | H38: m2 | I38: =+I$3 -> tbc | J38: =+J$3 -> tbc | K38: ear | L38: 375 | M38: =L38*G38 -> 0
A39: 32 | B39: door high | C39: =+'cut list'!F212 -> 1077 | E39: =+'cut list'!G212 -> 481 | F39: =+'cut list'!I212 -> 0 | G39: =+F39*E39/1000*C39/1000 -> 0 | H39: m2 | I39: =+I$3 -> tbc | J39: =+J$3 -> tbc | K39: ear | L39: 375 | M39: =L39*G39 -> 0
A40: 32 | B40: door high | C40: =+'cut list'!F218 -> 1077 | E40: =+'cut list'!G218 -> 461 | F40: =+'cut list'!I224 -> 0 | G40: =+F40*E40/1000*C40/1000 -> 0 | H40: m2 | I40: =+I$3 -> tbc | J40: =+J$3 -> tbc | K40: ear | L40: 375 | M40: =L40*G40 -> 0
B41: door high | C41: =+'cut list'!F200 -> 1077 | E41: =+'cut list'!G200 -> 369.5 | F41: =+'cut list'!I200 -> 0
...

Sheet pannels
A1: Door Board List
A2: Client Name : | C2: =+'input sheet'!C1 -> Adnaan | F2: Date : | J2: Panel colour | L2: edge colour
A3: Job Reference : | C3: =+'input sheet'!C2 -> bic | F3: Date Required : | J3: tbc | L3: tbc
A4: Phone Number : | F4: Cell:
A5: Delivery Address:
A6: Index | B6: Name | C6: Height | D6: Thickness | E6: Width | F6: Quantity | G6: Area | H6: Unit | I6: Door Series | J6: Door Color | K6: Door Shape | L6: Door Edge | M6: UnitPrice | N6: Total
A7: 1 | J7: =+J$3 -> tbc | L7: =+L$3 -> tbc | M7: 410 | N7: =M7*G7 -> 0
A8: 2 | J8: =+J$3 -> tbc | L8: =+L$3 -> tbc | M8: 410 | N8: =M8*G8 -> 0
A9: 3 | J9: =+J$3 -> tbc | L9: =+L$3 -> tbc | M9: 410 | N9: =M9*G9 -> 0
A10: 4 | J10: =+J$3 -> tbc | L10: =+L$3 -> tbc | M10: 410 | N10: =M10*G10 -> 0
A11: 5 | J11: =+J$3 -> tbc | L11: =+L$3 -> tbc | M11: 410 | N11: =M11*G11 -> 0
A12: 6 | J12: =+J$3 -> tbc | L12: =+L$3 -> tbc | M12: 410 | N12: =M12*G12 -> 0
A13: 7 | J13: =+J$3 -> tbc | L13: =+L$3 -> tbc | M13: 410 | N13: =M13*G13 -> 0
A14: 8 | J14: =+J$3 -> tbc | L14: =+L$3 -> tbc | M14: 410 | N14: =M14*G14 -> 0
A15: 9 | J15: =+J$3 -> tbc | L15: =+L$3 -> tbc | M15: 410 | N15: =M15*G15 -> 0
A16: 10 | J16: =+J$3 -> tbc | L16: =+L$3 -> tbc | M16: 410 | N16: =M16*G16 -> 0
A17: 11 | J17: =+J$3 -> tbc | L17: =+L$3 -> tbc | M17: 410 | N17: =M17*G17 -> 0
A18: 12 | J18: =+J$3 -> tbc | L18: =+L$3 -> tbc | M18: 410 | N18: =M18*G18 -> 0
... A25: 19 | J25: =+J$3 -> tbc | L25: =+L$3 -> tbc | M25: 410 | N25: =M25*G25 -> 0
A26: 20 | M26: 410 | N26: =M26*G26 -> 0
A27: 21 | M27: 410 | N27: =M27*G27 -> 0
A28: 22 | M28: 410 | N28: =M28*G28 -> 0
A29: 22 | M29: 410 | N29: =M29*G29 -> 0
A30: 22 | L30: 1L | M30: 410 | N30: =M30*G30 -> 0 | O30: 32mm edge
A31: 22 | L31: 1L | M31: 410 | N31: =M31*G31 -> 0 | O31: 32mm edge
A32: 16 | M32: 410 | N32: =M32*G32 -> 0
A33: 16 | M33: 410 | N33: =M33*G33 -> 0
A34: 16 | M34: 410 | N34: =M34*G34 -> 0
A35: Total: | N35: =SUM(N7:N25) -> 0

Sheet drawing

Sheet bic
A1: depth | B1: 560
A2: hanging size | B2: 984 | C2: 0
A3: shelf size | B3: 984 | C3: 0
A4: sides | B4: 2500 | C4: 3
A5: base | B5: 1800 | C5: 100 | D5: 3 | H5: door | J5: door | L5: door | N5: door
A6: base | B6: 520 | C6: 100 | D6: 7 | F6: 496 | H6: 496 | J6: =H6 -> 496 | L6: =J6 -> 496 | N6: =L6 -> 496
C8: =B12-C9-C10 -> 634
C9: 16
C10: 1800 | H10: =H14 -> 344 | J10: =SUM(H10:H19) -> 1800
H11: 16
B12: 2450 | H12: =H14 -> 344 | J12: =SUM(H12:H19) -> 1440
H13: 16
H14: =(C10-(16*5))/5 -> 344 | J14: =SUM(H14:H19) -> 1080
H15: 16
H16: =H14 -> 344 | J16: =SUM(H16:H19) -> 720
H17: 16
H18: =H14 -> 344 | J18: =SUM(H18:H19) -> 360
H19: =H15 -> 16
B20: 80
E21: 16 | F21: =(F6*2)-6 -> 986 | G21: 16 | H21: =H6-10 -> 486 | I21: 16 | J21: =J6-10 -> 486 | K21: 16 | Q21: =SUM(C21:P21) -> 2022
L26: =2900/6 -> 483.33333
F27: 988 | H27: 486
F28: 496 | H28: 496
F29: 496
A30: ceiling hight | B30: 2600
H31: door | J31: door | L31: door | N31: door
A32: space | B32: =B30-B41-B49 -> 70 | C32: caping | F32: =446*2 -> 892 | H32: 446 | J32: =H32 -> 446 | L32: =J32 -> 446 | N32: =L32 -> 446
F33: capping height
A34: over lap | B34: 50 | C34: =B34+B32+20 -> 140 | D34: =B34 -> 50 | F34: =B49+B41-B34 -> 2480
D35: 16 | F35: top cleat 66mm
D36: =B41-D34-D35 -> 2384
C37: =B41-C38-C39 -> 574 | D37: shelf hieght
C38: 16
C39: 1860 | H39: =H43 -> 449 | J39: shelf space
B40: pannel hieght | C40: shelf height | H40: 16
A41: paneel hiegth | B41: 2450 | H41: =H43 -> 449 | V41: 2450 | W41: 70
H42: 16 | T42: 2450 | U42: 2400 | V42: =U42-16 -> 2384 | W42: 50
H43: =(C39-(16*4))/4 -> 449
H44: 16
H45: =H43 -> 449
...

Sheet gola std
A13: 35 | H13: 57
A16: 177
A20: 2
A22: 177
A25: 35 | H25: 74
B26: =+(H25-A25)/2 -> 19.5
A30: 352
H32: =+A36+A30-B26 -> 334.5
A36: 2

Sheet dtc
A1: draws under mount | D1: DTC
A2: cupboard | C2: 825 | D2: 2
A3: shelf size | C3: =+C2-32 -> 793 | D3: subtract | E3: 86
A4: runners side | C4: 500 | D4: subtract | E4: 24
A5: back | D5: subtract | E5: 97
A7: draw bottom | C7: =+C3-E3 -> 707 | D7: =+C4-E4 -> 476 | E7: =+D2 -> 2
A8: back | C8: =+C3-E5 -> 696 | D8: 135 | E8: =+E7 -> 2
A10: cupboard | C10: 700 | D10: 4
A11: shelf size | C11: =+C10-32 -> 668 | D11: subtract | E11: 86
A12: runners side | C12: 350 | D12: subtract | E12: 24
A13: back | D13: subtract | E13: 97
A15: draw bottom | C15: =+C11-E11 -> 582 | D15: =+C12-E12 -> 326 | E15: =+D10 -> 4
A16: back | C16: =+C11-E13 -> 571 | D16: 96 | E16: =+E15 -> 4
A18: cupbaord | C18: 700 | D18: 4
A19: shelf size | C19: =+C18-32 -> 668 | D19: subtract | E19: 86
A20: runners side | C20: 270 | D20: subtract | E20: 24
A21: back | D21: subtract | E21: 97
A23: draw bottom | C23: =+C19-E19 -> 582 | D23: =+C20-E20 -> 246 | E23: =+D18 -> 4
A24: back | C24: =+C19-E21 -> 571 | D24: 96 | E24: =+E23 -> 4

Sheet sumit
A1: runners summit
A4: shelf size | C4: 568
A6: botom | C6: =+C4-75 -> 493 | D6: 490 | E6: or
A7: back | C7: =+C4-87 -> 481 | D7: 100 | E7: 183
A16: shelf size | C16: 568
A18: botom | C18: =+C16-75 -> 493 | D18: 490 | E18: or
A19: back | C19: =+C16-87 -> 481 | D19: 100 | E19: 183

Sheet gelmar

Sheet hardware list
G5: hinges straight | H5: hinges crn | I5: hinges reach in | J5: runner | K5: runner length | L5: bin
B6: =doors!B6 -> Name | C6: =doors!C6 -> Height | D6: =doors!E6 -> Width | E6: =doors!F6 -> Quantity
B7: =doors!B7 -> door | C7: =doors!C7 -> 717 | D7: =doors!E7 -> 538 | E7: =doors!F7 -> 0
B8: =doors!B8 -> draw front | C8: =doors!C8 -> 120 | D8: =doors!E8 -> 597 | E8: =doors!F8 -> 0
B9: =doors!B9 -> door | C9: =doors!C9 -> 717 | D9: =doors!E9 -> 297 | E9: =doors!F9 -> 0
B10: =doors!B10 -> draw front | C10: =doors!C10 -> 177 | D10: =doors!E10 -> 597 | E10: =doors!F10 -> 0
B11: =doors!B11 -> draw front | C11: =doors!C11 -> 177 | D11: =doors!E11 -> 697 | E11: =doors!F11 -> 0
B12: =doors!B12 -> draw front | C12: =doors!C12 -> 356 | D12: =doors!E12 -> 697 | E12: =doors!F12 -> 0
B13: =doors!B13 -> draw front | C13: =doors!C13 -> 356 | D13: =doors!E13 -> 597 | E13: =doors!F13 -> 0
B14: =doors!B14 -> door | C14: =doors!C14 -> 717 | D14: =doors!E14 -> 372 | E14: =doors!F14 -> 0
B15: =doors!B15 -> draw front | C15: =doors!C15 -> 177 | D15: =doors!E15 -> 747 | E15: =doors!F15 -> 0
B16: =doors!B16 -> draw front | C16: =doors!C16 -> 356 | D16: =doors!E16 -> 747 | E16: =doors!F16 -> 0
B17: =doors!B17 -> door | C17: =doors!C17 -> 717 | D17: =doors!E17 -> 316 | E17: =doors!F17 -> 0
... B39: =doors!B39 -> door high | C39: =doors!C39 -> 1077 | D39: =doors!E39 -> 481 | E39: =doors!F39 -> 0
B40: =doors!B56 -> door tall | C40: =doors!C56 -> 2293 | D40: =doors!E56 -> 447 | E40: =doors!F56 -> 0
B41: =doors!B57 -> door tall | C41: =doors!C57 -> 2293 | D41: =doors!E57 -> 297 | E41: =doors!F57 -> 0
